Workbook
Name Slicer_Category: #N/A
Name Slicer_Gender: #N/A
Name Slicer_Month: #N/A
Name Slicer_Region: #N/A
Name Slicer_Sub_Category: #N/A

Sheet Dashboard

Sheet Sheet2
A1: Q1 | B1: sales,profit,quantities | E1: Q2 | F1: Date & Time based questions | I1: Q3 | J1: Location based questions | N1: Q4 production/category questions | R1: Q5 Manager & Team Questions | V1: Q6 Customore/Gender based | Z1: Q7 Filter/Condition Based | AC1: Q8 Pivot table/ Pivot Charts | AH1: A. Sales, Quantity & Profit Analysis | AP1: B. Time-Based (Order Date / Ship Date) | BE1: C. Region, State, and City | BL1: D. Customer & Gender Analysis | BR1: E. Product & Category Insights
A2: 1 | B2: =SUM(Table1[Sales]) -> 589650.1 | C2: sales | E2: 1 | F2: Row Labels | G2: Count of Ship Date | I2: 1 | J2: Row Labels | K2: Sum of Sales | L2: Sum of Profit | N2: 1 | O2: Row Labels | P2: Sum of Sales | R2: 1 | S2: Row Labels | T2: Sum of Sales | V2: 1 | W2: =COUNTIF(Table1[Gender],"Male") -> 772 | X2: Male | Z2: 1 | AA2: All solve in data set | AC2: 1 | AD2: Row Labels | AE2: Sum of Sales | AF2: Sum of Profit | AH2: 1 | AI2: Row Labels | AJ2: Sum of Sales | AK2: Sum of Profit | AL2: Sum of Quantity | AP2: 1 | AQ2: Row Labels | AR2: Sum of Sales | BE2: 1 | BF2: Row Labels | BG2: Sum of Sales | BH2: Sum of Profit | BL2: 1 | BM2: Row Labels | BN2: Sum of Sales | BO2: Row Labels | BP2: Sum of Sales | BR2: 1 | BS2: Product Name | BT2: Sub-Category | BU2: Sum of Quantity
B3: =SUM(Table1[Profit]) -> 129071.84 | C3: profit | F3: 2021 | G3: 251 | J3: Andhra Pradesh | K3: 19183.83 | L3: 4586.73 | O3: Accessories | P3: 33645.465 | S3: Mohit | T3: 58751.97 | W3: =COUNTIF(Table1[Gender],"Female") -> 783 | X3: Female | Z3: 2 | AA3: All solve in data set | AD3: Accessories | AE3: 33645.465 | AF3: 7856.475 | AI3: Furniture | AJ3: 216056.25 | AK3: 42435.03 | AL3: 1296 | AQ3: January | AR3: 34932 | BF3: Andhra Pradesh | BG3: 19183.83 | BH3: 4586.73 | BM3: Furniture | BN3: 216056.25 | BO3: Furniture | BP3: 216056.25 | BS3: Ames Interoffice Envelope, with clear poly window | BT3: Envelopes | BU3: 19
B4: =SUM(Table1[Quantity]) -> 5758 | C4: quantities | F4: 2022 | G4: 346 | J4: Assam | K4: 5185.38 | L4: 887.1 | O4: Appliances | P4: 45209.19 | S4: Grand Total | T4: 58751.97 | Z4: 3 | AA4: All solve in data set | AD4: Appliances | AE4: 45209.19 | AF4: 10252.02 | AI4: Office Supplies | AJ4: 131334.82 | AK4: 30544.155 | AL4: 3122 | AQ4: February | AR4: 49296.96 | BF4: Assam | BG4: 5185.38 | BH4: 887.1 | BM4: Female | BN4: 117048.01 | BO4: Female | BP4: 117048.01 | BS4: Ames Interoffice Envelope, with clear poly window Total | BU4: 19
B5: =B3/B2 -> 0.21889564 | C5: Profit margin | F5: 2023 | G5: 394 | J5: Bihar | K5: 28615.14 | L5: 6139.08 | O5: Art | P5: 7878.375 | V5: 2 | W5: Row Labels | X5: Sum of Sales | Z5: 4 | AA5: All solve in data set | AD5: Bookcases | AE5: 88983 | AF5: 15937.2 | AI5: Technology | AJ5: 242259.03 | AK5: 56092.65 | AL5: 1340 | AQ5: March | AR5: 25852.2 | BF5: Bihar | BG5: 28615.14 | BH5: 6139.08 | BM5: Male | BN5: 99008.235 | BO5: Male | BP5: 99008.235 | BS5: Bush Stackable Bookrack, Pine | BT5: Bookcases | BU5: 23
B6: =SUM(Table1[Shipping Cost]) -> 61780.72 | C6: shipping cost | F6: 2024 | G6: 558 | J6: Chandigarh | K6: 491.94 | L6: 193.95 | O6: Binders | P6: 9794.025 | R6: 2 | S6: =AVERAGE(Table1[Profit]) -> 83.004395 | T6: Average profit per order | W6: Female | X6: 294880.58 | AD6: Chairs | AE6: 68874.42 | AF6: 13903.83 | AI6: Grand Total | AJ6: 589650.11 | AK6: 129071.84 | AL6: 5758 | AQ6: April | AR6: 41589.525 | AS6: LAST | BF6: Chandigarh | BG6: 491.94 | BH6: 193.95 | BM6: Office Supplies | BN6: 131334.83 | BO6: Office Supplies | BP6: 131334.83 | BS6: Bush Stackable Bookrack, Pine Total | BU6: 23
F7: 2025 | G7: 6 | J7: Chhattisgarh | K7: 22798.02 | L7: 6408.87 | O7: Bookcases | P7: 88983 | W7: Male | X7: 294769.53 | AD7: Copiers | AE7: 70386.06 | AF7: 18078.6 | AQ7: May | AR7: 50037.42 | BF7: Chhattisgarh | BG7: 22798.02 | BH7: 6408.87 | BM7: Female | BN7: 60055.995 | BO7: Female | BP7: 60055.995 | BS7: Cardinal Index Tab, Clear | BT7: Binders | BU7: 36
A8: 2 | B8: Row Labels | C8: Max of Sales | F8: Grand Total | G8: 1555 | J8: Delhi | K8: 31026.03 | L8: 5568.72 | O8: Chairs | P8: 68874.42 | R8: 3 | S8: Row Labels | T8: Average of Shipping Cost | W8: Grand Total | X8: 589650.11 | AD8: Furnishings | AE8: 16215.36 | AF8: 4340.43 | AH8: 2 | AI8: Sum of Sales | AJ8: Column Labels | AQ8: June | AR8: 65763.735 | BF8: Delhi | BG8: 31026.03 | BH8: 5568.72 | BM8: Male | BN8: 71278.83 | BO8: Male | BP8: 71278.83 | BS8: Cardinal Index Tab, Clear Total | BU8: 36
B9: Apple Smart Phone, with Caller ID | C9: 5751.54 | J9: Gujarat | K9: 29290.35 | L9: 8090.76 | O9: Copiers | P9: 70386.06 | S9: Manu | T9: 45.454252 | AD9: Machines | AE9: 33600.27 | AF9: 6878.1 | AI9: Row Labels | AJ9: East | AK9: North | AL9: South | AM9: West | AN9: Grand Total | AQ9: July | AR9: 36175.98 | BF9: Gujarat | BG9: 29290.35 | BH9: 8090.76 | BM9: Technology | BN9: 242259.03 | BO9: Technology | BP9: 242259.03 | BS9: Dania Corner Shelving, Metal | BT9: Bookcases | BU9: 19
B10: Grand Total | C10: 5751.54 | E10: 2 | F10: Average shipping time | G10: =AVERAGE(Table1[Diff order-ship date]) -> 3.3530547 | J10: Haryana | K10: 24657.42 | L10: 6565.32 | O10: Envelopes | P10: 9136.215 | S10: Meena | T10: 44.099603 | V10: 3 | W10: Row Labels | X10: Sum of Profit | AD10: Phones | AE10: 104627.23 | AF10: 23279.475 | AI10: Accessories | AJ10: 3656.13 | AK10: 10928.28 | AL10: 8452.53 | AM10: 10608.525 | AN10: 33645.465 | AQ10: August | AR10: 40282.575 | BF10: Haryana | BG10: 24657.42 | BH10: 6565.32 | BM10: Female | BN10: 117776.57 | BO10: Female | BP10: 117776.57 | BS10: Dania Corner Shelving, Metal Total | BU10: 19
J11: Jammu and Kashmir | K11: 7969.08 | L11: 2844.24 | O11: Fasteners | P11: 4746.12 | S11: Mohan | T11: 38.927402 | W11: Amy Cox | X11: 2181.42 | AD11: Storage | AE11: 27638.355 | AF11: 6381.345 | AI11: Appliances | AJ11: 5979.09 | AK11: 19840.92 | AL11: 7834.41 | AM11: 11554.77 | AN11: 45209.19 | AQ11: September | AR11: 84172.53 | BF11: Jammu and Kashmir | BG11: 7969.08 | BH11: 2844.24 | BM11: Male | BN11: 124482.46 | BO11: Male | BP11: 124482.46 | BS11: Enermax Memory Card, USB | BT11: Accessories | BU11: 28
A12: 3 | B12: Row Labels | C12: Count of Order ID | E12: 3 | F12: On the Dataset | J12: Jharkhand | K12: 12131.58 | L12: 4025.16 | O12: Furnishings | P12: 16215.36 | S12: Mohit | T12: 47.539213 | W12: Barry Franz | X12: 2075.7 | AD12: Tables | AE12: 41983.47 | AF12: 8253.57 | AI12: Art | AJ12: 720.72 | AK12: 2830.92 | AL12: 1496.55 | AM12: 2830.185 | AN12: 7878.375 | AQ12: October | AR12: 50837.16 | BF12: Jharkhand | BG12: 12131.58 | BH12: 4025.16 | BS12: Enermax Memory Card, USB Total | BU12: 28
B13: Arthur Gainer | C13: 17 | J13: Karnataka | K13: 31802.4 | L13: 9290.34 | O13: Labels | P13: 3572.595 | S13: Radha | T13: 43.401473 | W13: Cynthia Arntzen | X13: 3981.72 | AD13: Grand Total | AE13: 531162.82 | AF13: 115161.04 | AI13: Binders | AJ13: 1752.42 | AK13: 1843.47 | AL13: 2578.2 | AM13: 3619.935 | AN13: 9794.025 | AQ13: November | AR13: 61381.815 | BF13: Karnataka | BG13: 31802.4 | BH13: 9290.34 | BS13: Green Bar Note Cards, Premium | BT13: Paper | BU13: 23
B14: Grand Total | C14: 17 | E14: 3 | F14: =COUNTIF(Table1[ifs],"late Time") -> 412 | G14: took more than 10 days | J14: Kerala | K14: 20696.97 | L14: 4773.96 | O14: Machines | P14: 33600.27 | S14: Ram | T14: 30.003906 | W14: Denny Ordway | X14: 2284.68 | AI14: Bookcases | AJ14: 16732.2 | AK14: 19886.43 | AL14: 26297.61 | AM14: 26066.76 | AN14: 88983 | AQ14: December | AR14: 49328.205 | BF14: Kerala | BG14: 20696.97 | BH14: 4773.96 | BL14: 2 | BM14: Row Labels | BN14: Sum of Sales | BO14: Sum of Profit | BS14: Green Bar Note Cards, Premium Total | BU14: 23
J15: Madhya Pradesh | K15: 27069.78 | L15: 6268.02 | O15: Paper | P15: 12734.61 | S15: Renuka | T15: 49.206434 | W15: Vivek Grady | X15: 2537.64 | AI15: Chairs | AJ15: 11415.66 | AK15: 14451.24 | AL15: 14820.33 | AM15: 28187.19 | AN15: 68874.42 | AQ15: Grand Total | AR15: 589650.1 | BF15: Madhya Pradesh | BG15: 27069.78 | BH15: 6268.02 | BM15: Amy Cox | BN15: 6640.11 | BO15: 2181.42 | BS15: Ibico Binder Covers, Recycled | BT15: Binders | BU15: 32
A16: 4 | E16: 5 | F16: Row Labels | G16: Max of Sales | J16: Maharashtra | K16: 101322.4 | L16: 16105.755 | O16: Phones | P16: 104627.23 | S16: Rohit | T16: 38.022031 | W16: Grand Total | X16: 13061.16 | AI16: Copiers | AJ16: 2734.92 | AK16: 18644.91 | AL16: 20696.37 | AM16: 28309.86 | AN16: 70386.06 | BF16: Maharashtra | BG16: 101322.4 | BH16: 16105.755 | BM16: Art Foster | BN16: 6232.05 | BO16: 921.03 | BS16: Ibico Binder Covers, Recycled Total | BU16: 32
F17: November | G17: 5751.54 | J17: Manipur | K17: 5429.34 | L17: 354.42 | O17: Storage | P17: 27638.355 | S17: Suma | T17: 37.780977 | AI17: Envelopes | AJ17: 1560.15 | AK17: 1919.79 | AL17: 2968.35 | AM17: 2687.925 | AN17: 9136.215 | AP17: 2 | AR17: Column Labels | BF17: Manipur | BG17: 5429.34 | BH17: 354.42 | BM17: Barry Franz | BN17: 9366.12 | BO17: 2075.7 | BS17: Ibico Index Tab, Clear | BT17: Binders | BU17: 20
A18: 5 | F18: Grand Total | G18: 5751.54 | J18: Odisha | K18: 5280.36 | L18: 1395.96 | O18: Supplies | P18: 10625.34 | S18: Sumita | T18: 33.063433 | AI18: Fasteners | AJ18: 675.36 | AK18: 1102.17 | AL18: 1515.66 | AM18: 1452.93 | AN18: 4746.12 | AR18: 2021 | AT18: 2022 | AV18: 2023 | AX18: 2024 | AZ18: 2025 | BB18: Total Sum of Profit | BC18: Total Sum of Sales | BF18: Odisha | BG18: 5280.36 | BH18: 1395.96 | BM18: Craig Leslie | BN18: 6174.99 | BO18: 1253.88 | BS18: Ibico Index Tab, Clear Total | BU18: 20
J19: Puducherry | K19: 2936.67 | L19: 455.94 | O19: Tables | P19: 41983.47 | S19: Sunil | T19: 30.961791 | AI19: Furnishings | AJ19: 3203.46 | AK19: 3687.81 | AL19: 4964.73 | AM19: 4359.36 | AN19: 16215.36 | AQ19: Row Labels | AR19: Sum of Profit | AS19: Sum of Sales | AT19: Sum of Profit | AU19: Sum of Sales | AV19: Sum of Profit | AW19: Sum of Sales | AX19: Sum of Profit | AY19: Sum of Sales | AZ19: Sum of Profit | BA19: Sum of Sales | BF19: Puducherry | BG19: 2936.67 | BH19: 455.94 | BM19: Cynthia Arntzen | BN19: 10463.01 | BO19: 3981.72 | BS19: Kraft Clasp Envelope, Security-Tint | BT19: Envelopes | BU19: 18
B20: north | C20: =_xlfn.MAXIFS(Table1[Profit],Table1[Region],Sheet2!B20) -> 1423.44 | E20: 4 | F20: Row Labels | G20: Count of Order ID | J20: Punjab | K20: 14007.72 | L20: 3035.55 | O20: Grand Total | P20: 589650.1 | S20: Suraj | T20: 39.189699 | AI20: Labels | AJ20: 699.48 | AK20: 923.67 | AL20: 671.13 | AM20: 1278.315 | AN20: 3572.595 | AQ20: January | AR20: 540.51 | AS20: 3373.44 | AT20: 2206.98 | AU20: 7980.69 | AV20: 1139.97 | AW20: 7620.39 | AX20: 3720.57 | AY20: 15957.48 | BB20: 7608.03 | BC20: 34932 | BF20: Punjab | BG20: 14007.72 | BH20: 3035.55 | BM20: Larry Tron | BN20: 5676.81 | BO20: 556.86 | BS20: Kraft Clasp Envelope, Security-Tint Total | BU20: 18
B21: south | C21: =_xlfn.MAXIFS(Table1[Profit],Table1[Region],Sheet2!B21) -> 2097.03 | F21: January | G21: 99 | J21: Rajasthan | K21: 30992.79 | L21: 7041.03 | S21: Grand Total | T21: 39.730367 | AI21: Machines | AJ21: 5254.95 | AK21: 12517.2 | AL21: 6180.45 | AM21: 9647.67 | AN21: 33600.27 | AQ21: February | AR21: 3036.57 | AS21: 12377.4 | AT21: 4969.05 | AU21: 18359.97 | AV21: 809.46 | AW21: 9663.24 | AX21: 897.09 | AY21: 4895.31 | AZ21: 1440.24 | BA21: 4001.04 | BB21: 11152.41 | BC21: 49296.96 | BF21: Rajasthan | BG21: 30992.79 | BH21: 7041.03 | BM21: Laurel Beltran | BN21: 7596.45 | BO21: 1367.16 | BS21: Nokia Signal Booster, VoIP | BT21: Phones | BU21: 18
F22: February | G22: 93 | J22: Tamil Nadu | K22: 51911.46 | L22: 9992.4 | N22: 2 | O22: Row Labels | P22: Sum of Profit | AC22: 2 | AD22: Row Labels | AE22: Sum of Sales | AF22: Sum of Profit | AI22: Paper | AJ22: 1652.61 | AK22: 3799.32 | AL22: 2692.44 | AM22: 4590.24 | AN22: 12734.61 | AQ22: March | AR22: 1092.93 | AS22: 4214.13 | AT22: 721.32 | AU22: 3526.17 | AV22: 1064.46 | AW22: 5821.62 | AX22: 2877.72 | AY22: 12290.28 | BB22: 5756.43 | BC22: 25852.2 | BF22: Tamil Nadu | BG22: 51911.46 | BH22: 9992.4 | BM22: Lena Radford | BN22: 5788.17 | BO22: 1600.44 | BS22: Nokia Signal Booster, VoIP Total | BU22: 18
F23: March | G23: 98 | J23: Telangana | K23: 15921.75 | L23: 3512.61 | O23: Phones | P23: 23279.475 | AD23: January | AE23: 34932 | AF23: 7608.03 | AI23: Phones | AJ23: 23064.18 | AK23: 26578.29 | AL23: 23932.83 | AM23: 31051.935 | AN23: 104627.24 | AQ23: April | AR23: 955.62 | AS23: 2940.18 | AT23: 5325.15 | AU23: 18449.7 | AV23: 1262.22 | AW23: 5519.49 | AX23: 4292.475 | AY23: 14680.155 | BB23: 11835.465 | BC23: 41589.525 | BF23: Telangana | BG23: 15921.75 | BH23: 3512.61 | BM23: Mitch Gastineau | BN23: 5731.41 | BO23: 1264.35 | BS23: Office Star Chairmat, Black | BT23: Chairs | BU23: 29
F24: April | G24: 108 | J24: Tripura | K24: 646.29 | L24: 227.58 | O24: Grand Total | P24: 23279.475 | AD24: February | AE24: 49296.96 | AF24: 11152.41 | AI24: Storage | AJ24: 5543.58 | AK24: 3827.61 | AL24: 9802.77 | AM24: 8464.395 | AN24: 27638.355 | AQ24: May | AR24: 788.43 | AS24: 4492.17 | AT24: 2749.44 | AU24: 9368.1 | AV24: 5544.18 | AW24: 20695.89 | AX24: 3493.83 | AY24: 14905.08 | AZ24: 65.55 | BA24: 576.18 | BB24: 12641.43 | BC24: 50037.42 | BF24: Tripura | BG24: 646.29 | BH24: 227.58 | BM24: Vivek Grady | BN24: 10058.04 | BO24: 2537.64 | BS24: Office Star Chairmat, Black Total | BU24: 29
F25: May | G25: 135 | J25: Uttar Pradesh | K25: 76295.16 | L25: 17041.29 | AD25: March | AE25: 25852.2 | AF25: 5756.43 | AI25: Supplies | AJ25: 1119.12 | AK25: 3916.11 | AL25: 1803.63 | AM25: 3786.48 | AN25: 10625.34 | AQ25: June | AR25: 1480.98 | AS25: 10149.45 | AT25: 4342.305 | AU25: 20061.195 | AV25: 3905.265 | AW25: 13429.485 | AX25: 3246.885 | AY25: 22123.605 | BB25: 12975.435 | BC25: 65763.735 | BF25: Uttar Pradesh | BG25: 76295.16 | BH25: 17041.29 | BM25: Grand Total | BN25: 73727.16 | BO25: 17740.2 | BS25: Rubbermaid Photo Frame, Black | BT25: Furnishings | BU25: 18
F26: June | G26: 158 | J26: Uttarakhand | K26: 7752.33 | L26: 1515.33 | N26: 3 | O26: Row Labels | P26: Min of Profit | AD26: April | AE26: 41589.525 | AF26: 11835.465 | AI26: Tables | AJ26: 10557.99 | AK26: 15501.54 | AL26: 5745.09 | AM26: 10178.85 | AN26: 41983.47 | AQ26: July | AR26: 1712.13 | AS26: 8422.44 | AT26: 1519.26 | AU26: 4857.09 | AV26: 1108.68 | AW26: 4071.39 | AX26: 3248.79 | AY26: 18825.06 | BB26: 7588.86 | BC26: 36175.98 | BF26: Uttarakhand | BG26: 7752.33 | BH26: 1515.33 | BS26: Rubbermaid Photo Frame, Black Total | BU26: 18
F27: July | G27: 99 | J27: West Bengal | K27: 16235.91 | L27: 2751.72 | O27: Appliances | P27: 0 | AD27: May | AE27: 50037.42 | AF27: 12641.43 | AI27: Grand Total | AJ27: 96322.02 | AK27: 162199.68 | AL27: 142453.08 | AM27: 188675.32 | AN27: 589650.1 | AQ27: August | AR27: 1543.755 | AS27: 6791.085 | AT27: 1925.67 | AU27: 7575.03 | AV27: 2047.11 | AW27: 10970.52 | AX27: 2318.82 | AY27: 14945.94 | BB27: 7835.355 | BC27: 40282.575 | BF27: West Bengal | BG27: 16235.91 | BH27: 2751.72 | BL27: 3 | BM27: Region | BN27: Gender | BO27: Average of Profit | BS27: Sauder Classic Bookcase, Traditional | BT27: Bookcases | BU27: 18
F28: August | G28: 135 | J28: Grand Total | K28: 589650.1 | L28: 129071.83 | O28: Grand Total | P28: 0 | AD28: June | AE28: 65763.735 | AF28: 12975.435 | AQ28: September | AR28: 2846.19 | AS28: 14220.06 | AT28: 1620.375 | AU28: 11576.025 | AV28: 4500.51 | AW28: 21006.45 | AX28: 6399.735 | AY28: 37369.995 | BB28: 15366.81 | BC28: 84172.53 | BF28: Grand Total | BG28: 589650.1 | BH28: 129071.83 | BM28: East | BN28: Female | BO28: 99.523269 | BS28: Sauder Classic Bookcase, Traditional Total | BU28: 18
F29: September | G29: 162 | AD29: July | AE29: 36175.98 | AF29: 7588.86 | AH29: 3 | AI29: Row Labels | AJ29: Average of Profit | AQ29: October | AR29: 1764.18 | AS29: 9658.05 | AT29: 1799.01 | AU29: 8666.13 | AV29: 1472.865 | AW29: 7040.265 | AX29: 3933.435 | AY29: 25472.715 | BB29: 8969.49 | BC29: 50837.16 | BN29: Male | BO29: 99.491345 | BS29: Smead File Cart, Industrial | BT29: Storage | BU29: 18
F30: October | G30: 153 | I30: Q2 | J30: Row Labels | K30: Sum of Profit | N30: 4 | O30: Row Labels | P30: Max of Shipping Cost | AD30: August | AE30: 40282.575 | AF30: 7835.355 | AI30: First Class | AJ30: 82.414813 | AQ30: November | AR30: 4948.605 | AS30: 12941.985 | AT30: 2395.23 | AU30: 7958.55 | AV30: 2746.44 | AW30: 11078.64 | AX30: 7076.31 | AY30: 29402.64 | BB30: 17166.585 | BC30: 61381.815 | BE30: 2 | BF30: Row Labels | BG30: Sum of Sales | BM30: East Total | BO30: 99.506233 | BS30: Smead File Cart, Industrial Total | BU30: 18
F31: November | G31: 168 | J31: Gorakhpur | K31: 5575.11 | O31: Furniture | P31: 704.08 | AD31: September | AE31: 84172.53 | AF31: 15366.81 | AI31: Same Day | AJ31: 80.617385 | AQ31: December | AR31: 2157.99 | AS31: 8370.69 | AT31: 2831.46 | AU31: 14090.97 | AV31: 4143.3 | AW31: 18793.08 | AX31: 1042.785 | AY31: 8073.465 | BB31: 10175.535 | BC31: 49328.205 | BF31: Bangalore | BG31: 12499.98 | BM31: North | BN31: Female | BO31: 89.901509 | BS31: Stockwell Paper Clips, Assorted Sizes | BT31: Fasteners | BU31: 18
F32: December | G32: 147 | J32: Grand Total | K32: 5575.11 | O32: Office Supplies | P32: 439.65 | AD32: October | AE32: 50837.16 | AF32: 8969.49 | AI32: Second Class | AJ32: 82.846318 | AQ32: Grand Total | AR32: 22867.89 | AS32: 97951.08 | AT32: 32405.25 | AU32: 132469.62 | AV32: 29744.46 | AW32: 135710.46 | AX32: 42548.445 | AY32: 218941.72 | AZ32: 1505.79 | BA32: 4577.22 | BB32: 129071.83 | BC32: 589650.1 | BF32: Delhi | BG32: 31014.63 | BN32: Male | BO32: 96.224348 | BS32: Stockwell Paper Clips, Assorted Sizes Total | BU32: 18
F33: Grand Total | G33: 1555 | O33: Technology | P33: 658.69 | AD33: November | AE33: 61381.815 | AF33: 17166.585 | AI33: Standard Class | AJ33: 83.330781 | BF33: Gorakhpur | BG33: 22636.17 | BM33: North Total | BO33: 92.839394
I34: Q3 | J34: Row Labels | K34: Sum of Sales | L34: Average of Shipping Cost | N34: 5 | O34: Grand Total | P34: 704.08 | AD34: December | AE34: 49328.205 | AF34: 10175.535 | AI34: Grand Total | AJ34: 83.004395 | AP34: 3 | AQ34: Row Labels | AR34: Average of Diff order-ship date | BF34: Hyderabad | BG34: 12925.65 | BM34: South | BN34: Female | BO34: 79.211087
J35: East | K35: 96322.02 | L35: 43.933184 | AD35: Grand Total | AE35: 589650.1 | AF35: 129071.83 | AQ35: East | AR35: -11.919283 | BF35: Pune | BG35: 19749.87 | BN35: Male | BO35: 87.558932 | BR35: 2 | BS35: Row Labels | BT35: Sum of Shipping Cost | BU35: Sum of Sales
J36: North | K36: 162199.68 | L36: 41.30952 | AH36: 4 | AI36: Sum of Sales | AJ36: Column Labels | AQ36: North | AR36: 2.9267677 | BF36: Grand Total | BG36: 98826.3 | BM36: South Total | BO36: 83.620462 | BS36: Furniture | BT36: 22843.41 | BU36: 216056.25
J37: South | K37: 142453.08 | L37: 36.886231 | AI37: Row Labels | AJ37: Consumer | AK37: Corporate | AL37: Home Office | AM37: Grand Total | AQ37: South | AR37: 5.2641026 | BM37: West | BN37: Female | BO37: 72.156413 | BS37: Office Supplies | BT37: 12838.91 | BU37: 131334.82
J38: West | K38: 188675.32 | L38: 38.900037 | AI38: East | AJ38: 49417.92 | AK38: 20824.98 | AL38: 26079.12 | AM38: 96322.02 | AQ38: West | AR38: 8.5347985 | BE38: 3 | BF38: Row Labels | BG38: Sum of Sales | BH38: Count of Order ID | BN38: Male | BO38: 64.963118 | BS38: Technology | BT38: 26098.4 | BU38: 242259.03
J39: Grand Total | K39: 589650.11 | L39: 39.730367 | AI39: North | AJ39: 75200.76 | AK39: 53132.88 | AL39: 33866.04 | AM39: 162199.68 | AQ39: Grand Total | AR39: 3.3530547 | BF39: East | BG39: 96322.02 | BH39: 223 | BM39: West Total | BO39: 68.691511 | BS39: Grand Total | BT39: 61780.72 | BU39: 589650.11
AI40: South | AJ40: 72277.62 | AK40: 50006.22 | AL40: 20169.24 | AM40: 142453.08 | BF40: North | BG40: 162199.68 | BH40: 396
...

Sheet Dataset
A1: Row ID | B1: Order ID | C1: Ship Mode | D1: Customer ID | E1: Customer Name | F1: Segment | G1: City | H1: State | I1: Country | J1: Region | K1: Product ID | L1: Category | M1: Sub-Category | N1: Product Name | O1: Sales | P1: Quantity | Q1: Profit | R1: Profit Margin | S1: Shipping Cost | T1: Order Priority | U1: Target | V1: Manager | W1: Team lead | X1: Gender | Y1: Order Date | Z1: Ship Date | AA1: year | AB1: Month | AC1: Diff order-ship date | AD1: ifs | AE1: if profit | AF1: Concat | AG1: profit margin2
A2: 1 | B2: IN-2014-54694 | C2: Standard Class | D2: HG-14845 | E2: Harry Greene | F2: Consumer | G2: Rajkot | H2: Gujarat | I2: India | J2: West | K2: OFF-BI-10001312 | L2: Office Supplies | M2: Binders | N2: Cardinal 3-Hole Punch, Clear | O2: 56.52 | P2: 2 | Q2: 23.7 | R2: =Table1[[#This Row],[Profit]]/Table1[[#This Row],[Sales]] -> 0.41932059 | S2: 2.15 | T2: Medium | U2: 386 | V2: Mahesh | W2: Mohit | X2: Male | Y2: 45303 | Z2: 45424 | AA2: =YEAR(Z2) -> 2024 | AB2: =TEXT(Z2,"mmmm") -> May | AC2: =DATEDIF(Y2,Z2,"d") -> 121 | AD2: {=_xlfn.IFS(Table1[[#This Row],[Diff order-ship date]]>10,"late time",Table1[[#This Row],[Diff order-ship date]]>=0,"on time",Table1[[#This Row],[Diff order-ship date]]<0,"not appropriate")} -> late time | AE2: =IF(Q2<0,"Negative","Positive") -> Positive | AF2: =_xlfn.CONCAT(Table1[[#This Row],[Month]],Table1[[#This Row],[year]]) -> May2024 | AG2: =Q2/O2 -> 0.41932059
A3: 2 | B3: IN-2013-53763 | C3: Standard Class | D3: AR-10510 | E3: Andrew Roberts | F3: Consumer | G3: Durg | H3: Chhattisgarh | I3: India | J3: East | K3: OFF-BI-10002386 | L3: Office Supplies | M3: Binders | N3: Acco Index Tab, Clear | O3: 17.16 | P3: 2 | Q3: 2.04 | R3: =Table1[[#This Row],[Profit]]/Table1[[#This Row],[Sales]] -> 0.11888112 | S3: 1.5 | T3: Medium | U3: 401 | V3: Mahesh | W3: Mohan | X3: Female | Y3: 45287 | Z3: 45291 | AA3: =YEAR(Z3) -> 2023 | AB3: =TEXT(Z3,"mmmm") -> December | AC3: =DATEDIF(Y3,Z3,"d") -> 4 | AD3: {=_xlfn.IFS(Table1[[#This Row],[Diff order-ship date]]>10,"late time",Table1[[#This Row],[Diff order-ship date]]>=0,"on time",Table1[[#This Row],[Diff order-ship date]]<0,"not appropriate")} -> on time | AE3: =IF(Q3<0,"Negative","Positive") -> Positive | AF3: =_xlfn.CONCAT(Table1[[#This Row],[Month]],Table1[[#This Row],[year]]) -> December2023 | AG3: =Q3/O3 -> 0.11888112
A4: 3 | B4: IN-2014-15473 | C4: Standard Class | D4: TP-21130 | E4: Theone Pippenger | F4: Consumer | G4: Mangalore | H4: Karnataka | I4: India | J4: South | K4: OFF-BI-10004436 | L4: Office Supplies | M4: Binders | N4: Acco Hole Reinforcements, Recycled | O4: 14.04 | P4: 2 | Q4: 0.24 | R4: =Table1[[#This Row],[Profit]]/Table1[[#This Row],[Sales]] -> 0.017094017 | S4: 0.79 | T4: Medium | U4: 293 | V4: Mahesh | W4: Manu | X4: Female | Y4: 45334 | Z4: 45485 | AA4: =YEAR(Z4) -> 2024 | AB4: =TEXT(Z4,"mmmm") -> July | AC4: =DATEDIF(Y4,Z4,"d") -> 151 | AD4: {=_xlfn.IFS(Table1[[#This Row],[Diff order-ship date]]>10,"late time",Table1[[#This Row],[Diff order-ship date]]>=0,"on time",Table1[[#This Row],[Diff order-ship date]]<0,"not appropriate")} -> late time | AE4: =IF(Q4<0,"Negative","Positive") -> Positive | AF4: =_xlfn.CONCAT(Table1[[#This Row],[Month]],Table1[[#This Row],[year]]) -> July2024 | AG4: =Q4/O4 -> 0.017094017
A5: 4 | B5: IN-2014-24622 | C5: Standard Class | D5: MM-17920 | E5: Michael Moore | F5: Consumer | G5: Bijapur | H5: Karnataka | I5: India | J5: South | K5: OFF-BI-10002885 | L5: Office Supplies | M5: Binders | N5: Avery Hole Reinforcements, Recycled | O5: 9.54 | P5: 2 | Q5: 4.44 | R5: =Table1[[#This Row],[Profit]]/Table1[[#This Row],[Sales]] -> 0.46540881 | S5: 0.14 | T5: Medium | U5: 609 | V5: Mahesh | W5: Meena | X5: Female | Y5: 45587 | Z5: 45593 | AA5: =YEAR(Z5) -> 2024 | AB5: =TEXT(Z5,"mmmm") -> October | AC5: =DATEDIF(Y5,Z5,"d") -> 6 | AD5: {=_xlfn.IFS(Table1[[#This Row],[Diff order-ship date]]>10,"late time",Table1[[#This Row],[Diff order-ship date]]>=0,"on time",Table1[[#This Row],[Diff order-ship date]]<0,"not appropriate")} -> on time | AE5: =IF(Q5<0,"Negative","Positive") -> Positive | AF5: =_xlfn.CONCAT(Table1[[#This Row],[Month]],Table1[[#This Row],[year]]) -> October2024 | AG5: =Q5/O5 -> 0.46540881
A6: 5 | B6: IN-2012-29130 | C6: Standard Class | D6: JR-15700 | E6: Jocasta Rupert | F6: Consumer | G6: Kollam | H6: Kerala | I6: India | J6: South | K6: OFF-ST-10001290 | L6: Office Supplies | M6: Storage | N6: Rogers Shelving, Single Width | O6: 124.32 | P6: 2 | Q6: 54.66 | R6: =Table1[[#This Row],[Profit]]/Table1[[#This Row],[Sales]] -> 0.43967181 | S6: 11.12 | T6: Medium | U6: 750 | V6: Mahesh | W6: Mohan | X6: Male | Y6: 44466 | Z6: 44206 | AA6: =YEAR(Z6) -> 2021 | AB6: =TEXT(Z6,"mmmm") -> January | AC6: =DATEDIF(Y6,Z6,"d") -> -260 | AD6: {=_xlfn.IFS(Table1[[#This Row],[Diff order-ship date]]>10,"late time",Table1[[#This Row],[Diff order-ship date]]>=0,"on time",Table1[[#This Row],[Diff order-ship date]]<0,"not appropriate")} -> not appropriate | AE6: =IF(Q6<0,"Negative","Positive") -> Positive | AF6: =_xlfn.CONCAT(Table1[[#This Row],[Month]],Table1[[#This Row],[year]]) -> January2021 | AG6: =Q6/O6 -> 0.43967181
A7: 6 | B7: IN-2013-22648 | C7: Standard Class | D7: SF-20065 | E7: Sandra Flanagan | F7: Consumer | G7: Ratlam | H7: Madhya Pradesh | I7: India | J7: West | K7: OFF-ST-10000327 | L7: Office Supplies | M7: Storage | N7: Smead Folders, Wire Frame | O7: 33.12 | P7: 2 | Q7: 4.62 | R7: =Table1[[#This Row],[Profit]]/Table1[[#This Row],[Sales]] -> 0.13949275 | S7: 0.91 | T7: Medium | U7: 647 | V7: Mahesh | W7: Manu | X7: Female | Y7: 44728 | Z7: 44734 | AA7: =YEAR(Z7) -> 2022 | AB7: =TEXT(Z7,"mmmm") -> June | AC7: =DATEDIF(Y7,Z7,"d") -> 6 | AD7: {=_xlfn.IFS(Table1[[#This Row],[Diff order-ship date]]>10,"late time",Table1[[#This Row],[Diff order-ship date]]>=0,"on time",Table1[[#This Row],[Diff order-ship date]]<0,"not appropriate")} -> on time | AE7: =IF(Q7<0,"Negative","Positive") -> Positive | AF7: =_xlfn.CONCAT(Table1[[#This Row],[Month]],Table1[[#This Row],[year]]) -> June2022 | AG7: =Q7/O7 -> 0.13949275
A8: 7 | B8: IN-2011-24769 | C8: Standard Class | D8: JM-15535 | E8: Jessica Myrick | F8: Consumer | G8: Solapur | H8: Maharashtra | I8: India | J8: West | K8: OFF-EN-10003632 | L8: Office Supplies | M8: Envelopes | N8: Jiffy Mailers, Recycled | O8: 71.94 | P8: 2 | Q8: 10.74 | R8: =Table1[[#This Row],[Profit]]/Table1[[#This Row],[Sales]] -> 0.14929108 | S8: 8.46 | T8: Medium | U8: 167 | V8: Mahesh | W8: Meena | X8: Female | Y8: 45060 | Z8: 45066 | AA8: =YEAR(Z8) -> 2023 | AB8: =TEXT(Z8,"mmmm") -> May | AC8: =DATEDIF(Y8,Z8,"d") -> 6 | AD8: {=_xlfn.IFS(Table1[[#This Row],[Diff order-ship date]]>10,"late time",Table1[[#This Row],[Diff order-ship date]]>=0,"on time",Table1[[#This Row],[Diff order-ship date]]<0,"not appropriate")} -> on time | AE8: =IF(Q8<0,"Negative","Positive") -> Positive | AF8: =_xlfn.CONCAT(Table1[[#This Row],[Month]],Table1[[#This Row],[year]]) -> May2023 | AG8: =Q8/O8 -> 0.14929108
A9: 8 | B9: IN-2012-43165 | C9: Standard Class | D9: MM-17260 | E9: Magdelene Morse | F9: Consumer | G9: Puducherry | H9: Puducherry | I9: India | J9: South | K9: OFF-EN-10002007 | L9: Office Supplies | M9: Envelopes | N9: Kraft Clasp Envelope, with clear poly window | O9: 25.08 | P9: 2 | Q9: 3.96 | R9: =Table1[[#This Row],[Profit]]/Table1[[#This Row],[Sales]] -> 0.15789474 | S9: 1.88 | T9: Medium | U9: 189 | V9: Mahesh | W9: Mohit | X9: Female | Y9: 44325 | Z9: 44509 | AA9: =YEAR(Z9) -> 2021 | AB9: =TEXT(Z9,"mmmm") -> November | AC9: =DATEDIF(Y9,Z9,"d") -> 184 | AD9: {=_xlfn.IFS(Table1[[#This Row],[Diff order-ship date]]>10,"late time",Table1[[#This Row],[Diff order-ship date]]>=0,"on time",Table1[[#This Row],[Diff order-ship date]]<0,"not appropriate")} -> late time | AE9: =IF(Q9<0,"Negative","Positive") -> Positive | AF9: =_xlfn.CONCAT(Table1[[#This Row],[Month]],Table1[[#This Row],[year]]) -> November2021 | AG9: =Q9/O9 -> 0.15789474
A10: 9 | B10: IN-2012-32882 | C10: Standard Class | D10: TR-21325 | E10: Toby Ritter | F10: Consumer | G10: Kanpur | H10: Uttar Pradesh | I10: India | J10: North | K10: OFF-LA-10003273 | L10: Office Supplies | M10: Labels | N10: Harbour Creations Color Coded Labels, Adjustable | O10: 21.6 | P10: 2 | Q10: 1.26 | R10: =Table1[[#This Row],[Profit]]/Table1[[#This Row],[Sales]] -> 0.058333333 | S10: 1.38 | T10: Medium | U10: 774 | V10: Mahesh | W10: Mohan | X10: Male | Y10: 44585 | Z10: 44591 | AA10: =YEAR(Z10) -> 2022 | AB10: =TEXT(Z10,"mmmm") -> January | AC10: =DATEDIF(Y10,Z10,"d") -> 6 | AD10: {=_xlfn.IFS(Table1[[#This Row],[Diff order-ship date]]>10,"late time",Table1[[#This Row],[Diff order-ship date]]>=0,"on time",Table1[[#This Row],[Diff order-ship date]]<0,"not appropriate")} -> on time | AE10: =IF(Q10<0,"Negative","Positive") -> Positive | AF10: =_xlfn.CONCAT(Table1[[#This Row],[Month]],Table1[[#This Row],[year]]) -> January2022 | AG10: =Q10/O10 -> 0.058333333
A11: 10 | B11: IN-2011-59510 | C11: Standard Class | D11: DK-12985 | E11: Darren Koutras | F11: Consumer | G11: Meerut | H11: Uttar Pradesh | I11: India | J11: North | K11: OFF-LA-10002272 | L11: Office Supplies | M11: Labels | N11: Smead File Folder Labels, Alphabetical | O11: 17.4 | P11: 2 | Q11: 1.38 | R11: =Table1[[#This Row],[Profit]]/Table1[[#This Row],[Sales]] -> 0.079310345 | S11: 1.36 | T11: Medium | U11: 389 | V11: Mahesh | W11: Manu | X11: Female | Y11: 44790 | Z11: 44795 | AA11: =YEAR(Z11) -> 2022 | AB11: =TEXT(Z11,"mmmm") -> August | AC11: =DATEDIF(Y11,Z11,"d") -> 5 | AD11: {=_xlfn.IFS(Table1[[#This Row],[Diff order-ship date]]>10,"late time",Table1[[#This Row],[Diff order-ship date]]>=0,"on time",Table1[[#This Row],[Diff order-ship date]]<0,"not appropriate")} -> on time | AE11: =IF(Q11<0,"Negative","Positive") -> Positive | AF11: =_xlfn.CONCAT(Table1[[#This Row],[Month]],Table1[[#This Row],[year]]) -> August2022 | AG11: =Q11/O11 -> 0.079310345
A12: 11 | B12: IN-2014-63766 | C12: Standard Class | D12: MK-18160 | E12: Mike Kennedy | F12: Consumer | G12: Mangalore | H12: Karnataka | I12: India | J12: South | K12: OFF-LA-10004745 | L12: Office Supplies | M12: Labels | N12: Harbour Creations Shipping Labels, Adjustable | O12: 18.72 | P12: 2 | Q12: 9.12 | R12: =Table1[[#This Row],[Profit]]/Table1[[#This Row],[Sales]] -> 0.48717949 | S12: 1.26 | T12: Medium | U12: 585 | V12: Mahesh | W12: Meena | X12: Male | Y12: 44273 | Z12: 44278 | AA12: =YEAR(Z12) -> 2021 | AB12: =TEXT(Z12,"mmmm") -> March | AC12: =DATEDIF(Y12,Z12,"d") -> 5 | AD12: {=_xlfn.IFS(Table1[[#This Row],[Diff order-ship date]]>10,"late time",Table1[[#This Row],[Diff order-ship date]]>=0,"on time",Table1[[#This Row],[Diff order-ship date]]<0,"not appropriate")} -> on time | AE12: =IF(Q12<0,"Negative","Positive") -> Positive | AF12: =_xlfn.CONCAT(Table1[[#This Row],[Month]],Table1[[#This Row],[year]]) -> March2021 | AG12: =Q12/O12 -> 0.48717949
A13: 12 | B13: IN-2011-78823 | C13: Standard Class | D13: ME-17725 | E13: Max Engle | F13: Consumer | G13: Raipur | H13: Rajasthan | I13: India | J13: West | K13: OFF-FA-10000577 | L13: Office Supplies | M13: Fasteners | N13: Stockwell Push Pins, 12 Pack | O13: 26.82 | P13: 2 | Q13: 13.38 | R13: =Table1[[#This Row],[Profit]]/Table1[[#This Row],[Sales]] -> 0.49888143 | S13: 2.49 | T13: Medium | U13: 146 | V13: Mahesh | W13: Mohit | X13: Male | Y13: 45618 | Z13: 45622 | AA13: =YEAR(Z13) -> 2024 | AB13: =TEXT(Z13,"mmmm") -> November | AC13: =DATEDIF(Y13,Z13,"d") -> 4 | AD13: {=_xlfn.IFS(Table1[[#This Row],[Diff order-ship date]]>10,"late time",Table1[[#This Row],[Diff order-ship date]]>=0,"on time",Table1[[#This Row],[Diff order-ship date]]<0,"not appropriate")} -> on time | AE13: =IF(Q13<0,"Negative","Positive") -> Positive | AF13: =_xlfn.CONCAT(Table1[[#This Row],[Month]],Table1[[#This Row],[year]]) -> November2024 | AG13: =Q13/O13 -> 0.49888143
... A1556: 1555 | B1556: IN-2013-14675 | C1556: Standard Class | D1556: CS-12130 | E1556: Chad Sievert | F1556: Consumer | G1556: Bilaspur | H1556: Uttar Pradesh | I1556: India | J1556: North | K1556: TEC-CO-10002035 | L1556: Technology | M1556: Copiers | N1556: Canon Wireless Fax, High-Speed | O1556: 753.72 | P1556: 2 | Q1556: 60.24 | R1556: =Table1[[#This Row],[Profit]]/Table1[[#This Row],[Sales]] -> 0.079923579 | S1556: 74.65 | T1556: Medium | U1556: 542 | V1556: Suresh | W1556: Sunil | X1556: Female | Y1556: 44587 | Z1556: 44591 | AA1556: =YEAR(Z1556) -> 2022 | AB1556: =TEXT(Z1556,"mmmm") -> January | AC1556: =DATEDIF(Y1556,Z1556,"d") -> 4 | AD1556: {=_xlfn.IFS(Table1[[#This Row],[Diff order-ship date]]>10,"late time",Table1[[#This Row],[Diff order-ship date]]>=0,"on time",Table1[[#This Row],[Diff order-ship date]]<0,"not appropriate")} -> on time | AE1556: =IF(Q1556<0,"Negative","Positive") -> Positive | AF1556: =_xlfn.CONCAT(Table1[[#This Row],[Month]],Table1[[#This Row],[year]]) -> January2022 | AG1556: =Q1556/O1556 -> 0.079923579

Sheet Questions
A1: Sales, Profit, and Quantity Analysis
A3: 1. What is the total Sales, Profit, and Quantity sold across all records?
A5: 2. Which Product Name has the highest Sales?
A7: 3. Which Customer placed the highest number of orders?
A9: 4. What is the average Sales and Profit per order?
A11: 5. Which Region has the highest total profit? | F11: =_xlfn.MAXIFS(Dataset!$Q$2:$Q$1556,Dataset!$J$2:$J$1556,G11) -> 1080.54 | G11: west
F12: =_xlfn.MAXIFS(Dataset!$Q$2:$Q$1556,Dataset!$J$2:$J$1556,G12) -> 2817.99 | G12: east
F13: =_xlfn.MAXIFS(Dataset!$Q$2:$Q$1556,Dataset!$J$2:$J$1556,G13) -> 1423.44 | G13: north
F14: =_xlfn.MAXIFS(Dataset!$Q$2:$Q$1556,Dataset!$J$2:$J$1556,G14) -> 2097.03 | G14: south
A15: 2. Date & Time Based Questions
A17: 6. How many orders were placed in each year?
A19: 7. Calculate the number of days taken to ship each order (Ship Date - Order Date). What is the average shipping time?
A21: 8. Identify orders where shipping took more than 10 days.
A23: 9. Count how many orders were placed in each month.
A25: 10. Which month had the highest Sales?
A29: 3. Location-Based Questions
A31: 11. What are the total Sales and Profit by State?
A33: 12. Which City contributed the most to overall profit?
A35: 13. Group Sales by Region and compare average Shipping Cost per region.
A37: 14. Which states have negative profit?
A41: 4. Product/Category Questions
... A159: 25. Show Sub-Categories that contributed over ₹1000 in total Profit.
